---
title: ES6的Promise（转）
urlname: es6-promise
date: 2018-04-19 15:51:13
tags: javascript
---
原文链接：[大白话讲解Promise（一）](https://www.cnblogs.com/lvdabao/p/es6-promise-1.html)
```javascript
var p = new Promise(function(resolve, reject){
    //做一些异步操作
    setTimeout(function(){
        console.log('执行完成');
        resolve('随便什么数据');
    }, 2000);
});
```
**Promise**的构造函数接收一个参数，是函数，并且传入两个参数：`resolve`，`reject`，分别表示异步操作执行成功后的回调函数和异步操作执行失败后的回调函数。其实这里用“成功”和“失败”来描述并不准确，按照标准来讲，`resolve`是将Promise的状态置为`fullfiled`，`reject`是将Promise的状态置为`rejected`。不过在我们开始阶段可以先这么理解，后面再细究概念。
 
在上面的代码中，我们执行了一个异步操作，也就是`setTimeout`，2秒后，输出“执行完成”，并且调用`resolve`方法。
<!-- more --> 
运行代码，会在2秒后输出“执行完成”。注意！我只是new了一个对象，并没有调用它，我们传进去的函数就已经执行了，这是需要注意的一个细节。所以我们用Promise的时候一般是包在一个函数中，在需要的时候去运行这个函数，如：
```javascript
function runAsync(){
    var p = new Promise(function(resolve, reject){
        //做一些异步操作
        setTimeout(function(){
            console.log('执行完成');
            resolve('随便什么数据');
        }, 2000);
    });
    return p;            
}
runAsync()
```
这时候你应该有两个疑问：
1. 包装这么一个函数有毛线用？
2. resolve('随便什么数据');这是干毛的？
 
我们继续来讲。在我们包装好的函数最后，会return出Promise对象，也就是说，执行这个函数我们得到了一个Promise对象。还记得Promise对象上有`then`、`catch`方法吧？这就是强大之处了，看下面的代码：
```javascript
runAsync().then(function(data){
    console.log(data);
    //后面可以用传过来的数据做些其他操作
    //......
});
```
在`runAsync()`的返回上直接调用`then`方法，`then`接收一个参数，是函数，并且会拿到我们在`runAsync`中调用`resolve`时传的的参数。运行这段代码，会在2秒后输出“执行完成”，紧接着输出“随便什么数据”。
 
这时候你应该有所领悟了，原来`then`里面的函数就跟我们平时的回调函数一个意思，能够在`runAsync`这个异步任务执行完成之后被执行。这就是Promise的作用了，简单来讲，就是能把原来的回调写法分离出来，在异步操作执行完后，用链式调用的方式执行回调函数。
 
你可能会不屑一顾，那么牛逼轰轰的Promise就这点能耐？我把回调函数封装一下，给`runAsync`传进去不也一样吗，就像这样：
```javascript
function runAsync(callback){
    setTimeout(function(){
        console.log('执行完成');
        callback('随便什么数据');
    }, 2000);
}

runAsync(function(data){
    console.log(data);
});
```
效果也是一样的，还费劲用Promise干嘛。那么问题来了，有多层回调该怎么办？如果callback也是一个异步操作，而且执行完后也需要有相应的回调函数，该怎么办呢？总不能再定义一个callback2，然后给callback传进去吧。而Promise的优势在于，可以在then方法中继续写Promise对象并返回，然后继续调用then来进行回调操作。

所以，从表面上看，Promise只是能够简化层层回调的写法，而实质上，Promise的精髓是“状态”，用维护状态、传递状态的方式来使得回调函数能够及时调用，它比传递callback函数要简单、灵活的多。所以使用Promise的正确场景是这样的：
```javascript
runAsync1()
.then(function(data){
    console.log(data);
    return runAsync2();
})
.then(function(data){
    console.log(data);
    return runAsync3();
})
.then(function(data){
    console.log(data);
});
```
这样能够按顺序，每隔两秒输出每个异步回调中的内容，在runAsync2中传给resolve的数据，能在接下来的then方法中拿到。

到这里，你应该对“Promise是什么玩意”有了最基本的了解。那么我们接着来看看ES6的Promise还有哪些功能。我们光用了resolve，还没用reject呢，它是做什么的呢？事实上，我们前面的例子都是只有“执行成功”的回调，还没有“失败”的情况，reject的作用就是把Promise的状态置为rejected，这样我们在then中就能捕捉到，然后执行“失败”情况的回调。看下面的代码。
```javascript
function getNumber(){
    var p = new Promise(function(resolve, reject){
        //做一些异步操作
        setTimeout(function(){
            var num = Math.ceil(Math.random()*10); //生成1-10的随机数
            if(num<=5){
                resolve(num);
            }
            else{
                reject('数字太大了');
            }
        }, 2000);
    });
    return p;            
}

getNumber()
.then(
    function(data){
        console.log('resolved');
        console.log(data);
    }, 
    function(reason, data){
        console.log('rejected');
        console.log(reason);
    }
);
```
getNumber函数用来异步获取一个数字，2秒后执行完成，如果数字小于等于5，我们认为是“成功”了，调用resolve修改Promise的状态。否则我们认为是“失败”了，调用reject并传递一个参数，作为失败的原因。
 
运行getNumber并且在then中传了两个参数，then方法可以接受两个参数，第一个对应resolve的回调，第二个对应reject的回调。所以我们能够分别拿到他们传过来的数据。

我们知道Promise对象除了then方法，还有一个catch方法，它是做什么用的呢？其实它和then的第二个参数一样，用来指定reject的回调，用法是这样：
```javascript
getNumber()
.then(function(data){
    console.log('resolved');
    console.log(data);
})
.catch(function(reason){
    console.log('rejected');
    console.log(reason);
});
```
效果和写在then的第二个参数里面一样。不过它还有另外一个作用：在执行resolve的回调（也就是上面then中的第一个参数）时，如果抛出异常了（代码出错了），那么并不会报错卡死js，而是会进到这个catch方法中。请看下面的代码：
```javascript
getNumber()
.then(function(data){
    console.log('resolved');
    console.log(data);
    console.log(somedata); //此处的somedata未定义
})
.catch(function(reason){
    console.log('rejected');
    console.log(reason);
});
```
在resolve的回调中，我们console.log(somedata);而somedata这个变量是没有被定义的。如果我们不用Promise，代码运行到这里就直接在控制台报错了，不往下运行了。

也就是说进到catch方法里面去了，而且把错误原因传到了reason参数中。即便是有错误的代码也不会报错了，这与我们的try/catch语句有相同的功能。